[ERROR] 2021-03-05 22:43:55,280 | /home/hp/frappe-bench/apps/frappe/frappe/app.py:
Site: gne3.gndec.ac.in
Form Dict: {
 "action": "Save",
 "cmd": "frappe.desk.form.save.savedocs",
 "doc": "{\"docstatus\":0,\"doctype\":\"Address\",\"name\":\"New Address 4\",\"__islocal\":1,\"__unsaved\":1,\"owner\":\"Administrator\",\"address_type\":\"Billing\",\"country\":\"India\",\"gst_state\":\"Punjab\",\"is_primary_address\":1,\"is_shipping_address\":1,\"disabled\":0,\"is_your_company_address\":0,\"links\":[{\"docstatus\":0,\"doctype\":\"Dynamic Link\",\"name\":\"New Dynamic Link 3\",\"__islocal\":1,\"__unsaved\":1,\"owner\":\"Administrator\",\"parent\":\"New Address 4\",\"parentfield\":\"links\",\"parenttype\":\"Address\",\"idx\":1,\"link_doctype\":\"Customer\",\"link_name\":\"Lakshay Chopra\"}],\"address_title\":\"Company Home Office\",\"email_id\":\"lakshay@gmail.com\",\"phone\":\"9000000009\",\"address_line1\":\"Hno 53 ABC Road\",\"address_line2\":\"XYZ Nagar\",\"city\":\"Ludhiana\",\"county\":\"\",\"state\":\"Punjab\",\"fax\":\"9000000009\",\"gstin\":\"27AAA021451BH\",\"tax_category\":\"GSTTAX\"}"
}
Request Error
Traceback (most recent call last):
  File "/home/hp/frappe-bench/apps/frappe/frappe/app.py", line 67, in application
    response = frappe.api.handle()
  File "/home/hp/frappe-bench/apps/frappe/frappe/api.py", line 59, in handle
    return frappe.handler.handle()
  File "/home/hp/frappe-bench/apps/frappe/frappe/handler.py", line 24, in handle
    data = execute_cmd(cmd)
  File "/home/hp/frappe-bench/apps/frappe/frappe/handler.py", line 64, in execute_cmd
    return frappe.call(method, **frappe.form_dict)
  File "/home/hp/frappe-bench/apps/frappe/frappe/__init__.py", line 1071, in call
    return fn(*args, **newargs)
  File "/home/hp/frappe-bench/apps/frappe/frappe/desk/form/save.py", line 21, in savedocs
    doc.save()
  File "/home/hp/frappe-bench/apps/frappe/frappe/model/document.py", line 273, in save
    return self._save(*args, **kwargs)
  File "/home/hp/frappe-bench/apps/frappe/frappe/model/document.py", line 296, in _save
    self.insert()
  File "/home/hp/frappe-bench/apps/frappe/frappe/model/document.py", line 230, in insert
    self.run_before_save_methods()
  File "/home/hp/frappe-bench/apps/frappe/frappe/model/document.py", line 896, in run_before_save_methods
    self.run_method("validate")
  File "/home/hp/frappe-bench/apps/frappe/frappe/model/document.py", line 797, in run_method
    out = Document.hook(fn)(self, *args, **kwargs)
  File "/home/hp/frappe-bench/apps/frappe/frappe/model/document.py", line 1073, in composer
    return composed(self, method, *args, **kwargs)
  File "/home/hp/frappe-bench/apps/frappe/frappe/model/document.py", line 1058, in runner
    add_to_return_value(self, f(self, method, *args, **kwargs))
  File "/home/hp/frappe-bench/apps/erpnext/erpnext/regional/india/utils.py", line 31, in validate_gstin_for_india
    gst_category = frappe.db.get_value(link_doctype, {'name': link_name}, ['gst_category'])
  File "/home/hp/frappe-bench/apps/frappe/frappe/database/database.py", line 401, in get_value
    order_by, cache=cache)
  File "/home/hp/frappe-bench/apps/frappe/frappe/database/database.py", line 445, in get_values
    out = self._get_values_from_table(fields, filters, doctype, as_dict, debug, order_by, update)
  File "/home/hp/frappe-bench/apps/frappe/frappe/database/database.py", line 592, in _get_values_from_table
    as_dict=as_dict, debug=debug, update=update)
  File "/home/hp/frappe-bench/apps/frappe/frappe/database/database.py", line 156, in sql
    self._cursor.execute(query, values)
  File "/home/hp/frappe-bench/env/lib/python3.6/site-packages/pymysql/cursors.py", line 170, in execute
    result = self._query(query)
  File "/home/hp/frappe-bench/env/lib/python3.6/site-packages/pymysql/cursors.py", line 328, in _query
    conn.query(q)
  File "/home/hp/frappe-bench/env/lib/python3.6/site-packages/pymysql/connections.py", line 517, in query
    self._affected_rows = self._read_query_result(unbuffered=unbuffered)
  File "/home/hp/frappe-bench/env/lib/python3.6/site-packages/pymysql/connections.py", line 732, in _read_query_result
    result.read()
  File "/home/hp/frappe-bench/env/lib/python3.6/site-packages/pymysql/connections.py", line 1075, in read
    first_packet = self.connection._read_packet()
  File "/home/hp/frappe-bench/env/lib/python3.6/site-packages/pymysql/connections.py", line 684, in _read_packet
    packet.check_error()
  File "/home/hp/frappe-bench/env/lib/python3.6/site-packages/pymysql/protocol.py", line 220, in check_error
    err.raise_mysql_exception(self._data)
  File "/home/hp/frappe-bench/env/lib/python3.6/site-packages/pymysql/err.py", line 109, in raise_mysql_exception
    raise errorclass(errno, errval)
pymysql.err.InternalError: (1054, "Unknown column 'gst_category' in 'field list'")
[ERROR] 2021-03-05 22:43:55,341 | /home/hp/frappe-bench/apps/frappe/frappe/utils/error.py:
New Exception collected with id: 2021-03-05 22:43:55.280968-106.192.22.30-425
[ERROR] 2021-03-07 11:14:22,693 | /home/hp/frappe-bench/apps/frappe/frappe/app.py:
Site: gne3.gndec.ac.in
Form Dict: {
 "cmd": "frappe.desk.search.search_link",
 "doctype": "Address",
 "filters": "{\"link_doctype\":\"Supplier\"}",
 "ignore_user_permissions": "0",
 "query": "frappe.contacts.doctype.address.address.address_query",
 "reference_doctype": "Sales Invoice",
 "txt": ""
}
Request Error
Traceback (most recent call last):
  File "/home/hp/frappe-bench/apps/frappe/frappe/app.py", line 67, in application
    response = frappe.api.handle()
  File "/home/hp/frappe-bench/apps/frappe/frappe/api.py", line 59, in handle
    return frappe.handler.handle()
  File "/home/hp/frappe-bench/apps/frappe/frappe/handler.py", line 24, in handle
    data = execute_cmd(cmd)
  File "/home/hp/frappe-bench/apps/frappe/frappe/handler.py", line 64, in execute_cmd
    return frappe.call(method, **frappe.form_dict)
  File "/home/hp/frappe-bench/apps/frappe/frappe/__init__.py", line 1071, in call
    return fn(*args, **newargs)
  File "/home/hp/frappe-bench/apps/frappe/frappe/desk/search.py", line 56, in search_link
    frappe.response['results'] = build_for_autosuggest(frappe.response["values"])
  File "/home/hp/frappe-bench/env/lib/python3.6/site-packages/werkzeug/local.py", line 378, in <lambda>
    __getitem__ = lambda x, i: x._get_current_object()[i]
KeyError: 'values'
[ERROR] 2021-03-07 11:14:22,710 | /home/hp/frappe-bench/apps/frappe/frappe/utils/error.py:
New Exception collected with id: 2021-03-07 11:14:22.708595-132.154.155.53-157
